Workbook

Sheet Assumptions
A1: AURORA OUTDOOR SUPPLY CO. — MODEL ASSUMPTIONS
A2: Multi-Channel Outdoor Retailer | Three Statement Financial Model | All figures in $000s
D4: Historical Results | I4: Forecast Period
B5: Assumptions | C5: Notes | D5: FY21 | E5: FY22 | F5: FY23 | G5: FY24 | H5: FY25 | I5: FY26 | J5: FY27 | K5: FY28 | L5: FY29 | M5: FY30
B6: REVENUE
B7: Revenue Growth (YoY %) | C7: Overall store + online revenue | E7: 0.158 | F7: 0.112 | G7: 0.084 | H7: 0.059 | I7: 0.1 | J7: 0.1 | K7: 0.1 | L7: 0.08 | M7: 0.08
B8: Online Channel Mix (%) | C8: % of revenue via e-commerce | D8: 0.22 | E8: 0.25 | F8: 0.28 | G8: 0.3 | H8: 0.32 | I8: 0.34 | J8: 0.36 | K8: 0.38 | L8: 0.4 | M8: 0.42
B9: Store Channel Mix (%) | C9: % of revenue via physical stores | D9: 0.78 | E9: 0.75 | F9: 0.72 | G9: 0.7 | H9: 0.68 | I9: 0.66 | J9: 0.64 | K9: 0.62 | L9: 0.6 | M9: 0.58
B10: MARGINS
B11: Cost of Goods Sold (% Rev) | C11: Blended COGS across all channels | D11: 0.383 | E11: 0.407 | F11: 0.374 | G11: 0.37 | H11: 0.376 | I11: 0.37 | J11: 0.37 | K11: 0.37 | L11: 0.36 | M11: 0.36
B12: Gross Margin (%) | C12: Derived from model | D12: ='Three Statement Model'!D13 -> 0.61744782 | E12: ='Three Statement Model'!E13 -> 0.59348272 | F12: ='Three Statement Model'!F13 -> 0.62600023 | G12: ='Three Statement Model'!G13 -> 0.6300855 | H12: ='Three Statement Model'!H13 -> 0.62386915 | I12: ='Three Statement Model'!I13 -> 0.63 | J12: ='Three Statement Model'!J13 -> 0.63 | K12: ='Three Statement Model'!K13 -> 0.63 | ... M12: ='Three Statement Model'!M13 -> 0.64
B14: OPERATING EXPENSES
B15: Store Labour (% Rev) | C15: In-store staff wages & oncosts | D15: 0.13 | E15: 0.096 | F15: 0.091 | G15: 0.081 | H15: 0.084 | I15: 0.085 | J15: 0.085 | K15: 0.085 | L15: 0.08 | M15: 0.08
B16: Fulfilment & Logistics (% Rev) | C16: Online pick/pack & freight | D16: 0.04 | E16: 0.042 | F16: 0.043 | G16: 0.045 | H16: 0.046 | I16: 0.047 | J16: 0.047 | K16: 0.046 | L16: 0.045 | M16: 0.045
B17: Marketing & Promotions (% Rev) | C17: Paid, brand, catalogue | D17: 0.035 | E17: 0.038 | F17: 0.04 | G17: 0.038 | H17: 0.037 | I17: 0.04 | J17: 0.04 | K17: 0.038 | L17: 0.038 | M17: 0.038
B18: Rent & Occupancy ($000s) | C18: Fixed store leases + DC | D18: 10963 | E18: 10125 | F18: 10087 | G18: 11020 | H18: 11412 | I18: 12000 | J18: 12000 | K18: 13000 | L18: 13000 | M18: 14000
B19: G&A (% Rev) | C19: Corporate overhead | D19: 0.03 | E19: 0.025 | F19: 0.024 | G19: 0.022 | H19: 0.023 | I19: 0.023 | J19: 0.023 | K19: 0.023 | L19: 0.022 | M19: 0.022
B21: D&A & CAPEX
B22: Depreciation (% Opening PP&E) | C22: Straight-line on opening balance | D22: 0.429 | E22: 0.429 | F22: 0.429 | G22: 0.429 | H22: 0.429 | I22: 0.35 | J22: 0.35 | K22: 0.35 | L22: 0.35 | M22: 0.35
B23: Capital Expenditures ($000s) | C23: Store refits, IT, DC equipment | D23: 15000 | E23: 15000 | F23: 15000 | G23: 15000 | H23: 15000 | I23: 15000 | J23: 16000 | K23: 16000 | L23: 17000 | M23: 17000
B25: BALANCE SHEET
B26: Accounts Receivable (Days) | C26: Mostly wholesale; retail is near-zero | D26: 18 | E26: 18 | F26: 18 | G26: 18 | H26: 18 | I26: 18 | J26: 18 | K26: 18 | L26: 18 | M26: 18
B27: Inventory (Days) | C27: Days of COGS held; outdoor retail seasonal | D27: 73 | E27: 73 | F27: 73 | G27: 73 | H27: 73 | I27: 80 | J27: 85 | K27: 85 | L27: 85 | M27: 85
B28: Accounts Payable (Days) | C28: Supplier payment terms | D28: 36 | E28: 36 | F28: 36 | G28: 37 | H28: 36 | I28: 38 | J28: 38 | K28: 38 | L28: 38 | M28: 38
B30: FINANCING
B31: Interest Rate (% of Debt) | C31: Blended borrowing rate | D31: 0.05 | E31: 0.05 | F31: 0.05 | G31: 0.05 | H31: 0.05 | I31: 0.07 | J31: 0.07 | K31: 0.07 | L31: 0.07 | M31: 0.07
B32: Tax Rate (%) | C32: Effective corporate tax rate | D32: 0.31 | E32: 0.292 | F32: 0.287 | G32: 0.29 | H32: 0.291 | I32: 0.28 | J32: 0.28 | K32: 0.28 | L32: 0.28 | M32: 0.28
B33: Debt Issuance / (Repayment) ($000s) | C33: Planned debt movements | D33: 0 | E33: 0 | F33: -20000 | G33: 0 | H33: 0 | I33: 0 | J33: 0 | K33: 0 | L33: -10000 | M33: 0
B34: Equity Issued / (Repaid) ($000s) | C34: Equity raise or buyback | D34: 70000 | E34: 0 | F34: 0 | G34: 0 | H34: 0 | I34: 0 | J34: 0 | K34: 0 | L34: 0 | M34: 0
B35: Days in Year | D35: 365 | E35: 365 | F35: 365 | G35: 365 | H35: 365 | I35: 365 | J35: 365 | K35: 365 | L35: 365 | M35: 365
B38: COLOUR LEGEND
B39: Blue text = Hardcoded input (user-editable)
B40: Black text = Calculated formula
B41: Green text = Cross-sheet link

Sheet Three Statement Model
A1: AURORA OUTDOOR SUPPLY CO. — THREE STATEMENT MODEL
A2: Multi-Channel Outdoor Retailer | All figures in $000s unless noted | FY21-FY25 Historical | FY26-FY30 Forecast
C3: Balance Sheet Check → | D3: =IF(ABS(D42-D55)<1,"OK","ERROR") -> OK | E3: =IF(ABS(E42-E55)<1,"OK","ERROR") -> OK | F3: =IF(ABS(F42-F55)<1,"OK","ERROR") -> OK | G3: =IF(ABS(G42-G55)<1,"OK","ERROR") -> OK | H3: =IF(ABS(H42-H55)<1,"OK","ERROR") -> OK | I3: =IF(ABS(I42-I55)<1,"OK","ERROR") -> OK | J3: =IF(ABS(J42-J55)<1,"OK","ERROR") -> OK | K3: =IF(ABS(K42-K55)<1,"OK","ERROR") -> OK | ... M3: =IF(ABS(M42-M55)<1,"OK","ERROR") -> OK
D4: Historical Results | I4: Forecast Period
D5: FY21 | E5: FY22 | F5: FY23 | G5: FY24 | H5: FY25 | I5: FY26 | J5: FY27 | K5: FY28 | L5: FY29 | M5: FY30
C7: INCOME STATEMENT ($000s)
C8: Revenue ($000s) | D8: 102007 | E8: 118086 | F8: 131345 | G8: 142341 | H8: 150772 | I8: =H8*(1+Assumptions!I7) -> 165849.2 | J8: =I8*(1+Assumptions!J7) -> 182434.12 | K8: =J8*(1+Assumptions!K7) -> 200677.53 | L8: =K8*(1+Assumptions!L7) -> 216731.73 | M8: =L8*(1+Assumptions!M7) -> 234070.27
C9: Online Channel | D9: =D8*Assumptions!D8 -> 22441.54 | E9: =E8*Assumptions!E8 -> 29521.5 | F9: =F8*Assumptions!F8 -> 36776.6 | G9: =G8*Assumptions!G8 -> 42702.3 | H9: =H8*Assumptions!H8 -> 48247.04 | I9: =I8*Assumptions!I8 -> 56388.728 | J9: =J8*Assumptions!J8 -> 65676.283 | K9: =K8*Assumptions!K8 -> 76257.462 | ... M9: =M8*Assumptions!M8 -> 98309.515
C10: Store Channel | D10: =D8-D9 -> 79565.46 | E10: =E8-E9 -> 88564.5 | F10: =F8-F9 -> 94568.4 | G10: =G8-G9 -> 99638.7 | H10: =H8-H9 -> 102524.96 | I10: =I8-I9 -> 109460.47 | J10: =J8-J9 -> 116757.84 | K10: =K8-K9 -> 124420.07 | ... M10: =M8-M9 -> 135760.76
C11: Cost of Goods Sold | D11: 39023 | E11: 48004 | F11: 49123 | G11: 52654 | H11: 56710 | I11: =I8*Assumptions!I11 -> 61364.204 | J11: =J8*Assumptions!J11 -> 67500.624 | K11: =K8*Assumptions!K11 -> 74250.687 | L11: =L8*Assumptions!L11 -> 78023.424 | M11: =M8*Assumptions!M11 -> 84265.298
C12: Gross Profit | D12: 62984 | E12: 70082 | F12: 82222 | G12: 89687 | H12: 94062 | I12: =I8-I11 -> 104485 | J12: =J8-J11 -> 114933.5 | K12: =K8-K11 -> 126426.85 | L12: =L8-L11 -> 138708.31 | M12: =M8-M11 -> 149804.97
C13: Gross Margin (%) | D13: =IF(D8=0,"-",D12/D8) -> 0.61744782 | E13: =IF(E8=0,"-",E12/E8) -> 0.59348272 | F13: =IF(F8=0,"-",F12/F8) -> 0.62600023 | G13: =IF(G8=0,"-",G12/G8) -> 0.6300855 | H13: =IF(H8=0,"-",H12/H8) -> 0.62386915 | I13: =IF(I8=0,"-",I12/I8) -> 0.63 | J13: =IF(J8=0,"-",J12/J8) -> 0.63 | K13: =IF(K8=0,"-",K12/K8) -> 0.63 | ... M13: =IF(M8=0,"-",M12/M8) -> 0.64
C15: Operating Expenses
C16: Store Labour | D16: 13260.91 | E16: 11336.256 | F16: 11952.395 | G16: 11529.621 | H16: 12664.848 | I16: =I8*Assumptions!I15 -> 14097.182 | J16: =J8*Assumptions!J15 -> 15506.9 | K16: =K8*Assumptions!K15 -> 17057.59 | L16: =L8*Assumptions!L15 -> 17338.539 | M16: =M8*Assumptions!M15 -> 18725.622
C17: Fulfilment & Logistics | D17: 4080.28 | E17: 4959.612 | F17: 5647.835 | G17: 6405.345 | H17: 6935.512 | I17: =I8*Assumptions!I16 -> 7794.9124 | J17: =J8*Assumptions!J16 -> 8574.4036 | K17: =K8*Assumptions!K16 -> 9231.1665 | L17: =L8*Assumptions!L16 -> 9752.9281 | M17: =M8*Assumptions!M16 -> 10533.162
C18: Marketing & Promotions | D18: 3570.245 | E18: 4487.268 | F18: 5253.8 | G18: 5408.958 | H18: 5578.564 | I18: =I8*Assumptions!I17 -> 6633.968 | J18: =J8*Assumptions!J17 -> 7297.3648 | K18: =K8*Assumptions!K17 -> 7625.7462 | L18: =L8*Assumptions!L17 -> 8235.8059 | M18: =M8*Assumptions!M17 -> 8894.6704
C19: Rent & Occupancy | D19: 10963 | E19: 10125 | F19: 10087 | G19: 11020 | H19: 11412 | I19: =Assumptions!I18 -> 12000 | J19: =Assumptions!J18 -> 12000 | K19: =Assumptions!K18 -> 13000 | L19: =Assumptions!L18 -> 13000 | M19: =Assumptions!M18 -> 14000
C20: General & Administrative | D20: 3060.21 | E20: 2952.15 | F20: 3152.28 | G20: 3131.502 | H20: 3467.756 | I20: =I8*Assumptions!I19 -> 3814.5316 | J20: =J8*Assumptions!J19 -> 4195.9848 | K20: =K8*Assumptions!K19 -> 4615.5832 | L20: =L8*Assumptions!L19 -> 4768.0982 | M20: =M8*Assumptions!M19 -> 5149.546
C21: Depreciation & Amortisation | D21: 19500 | E21: 18150 | F21: 17205 | G21: 16544 | H21: 16080 | I21: =I93 -> 13132.35 | J21: =J93 -> 13786.028 | K21: =K93 -> 14560.918 | L21: =L93 -> 15064.597 | M21: =M93 -> 15741.988
C22: Total Operating Expenses | D22: =D16+D17+D18+D19+D20+D21 -> 54434.645 | E22: =E16+E17+E18+E19+E20+E21 -> 52010.286 | F22: =F16+F17+F18+F19+F20+F21 -> 53298.31 | G22: =G16+G17+G18+G19+G20+G21 -> 54039.426 | H22: =H16+H17+H18+H19+H20+H21 -> 56138.68 | I22: =I16+I17+I18+I19+I20+I21 -> 57472.944 | J22: =J16+J17+J18+J19+J20+J21 -> 61360.681 | K22: =K16+K17+K18+K19+K20+K21 -> 66091.004 | ... M22: =M16+M17+M18+M19+M20+M21 -> 73044.988
C24: EBIT | D24: =D12-D22 -> 8549.355 | E24: =E12-E22 -> 18071.714 | F24: =F12-F22 -> 28923.69 | G24: =G12-G22 -> 35647.574 | H24: =H12-H22 -> 37923.32 | I24: =I12-I22 -> 47012.052 | J24: =J12-J22 -> 53572.815 | K24: =K12-K22 -> 60335.841 | ... M24: =M12-M22 -> 76759.987
C25: EBIT Margin (%) | D25: =IF(D8=0,"-",D24/D8) -> 0.083811454 | E25: =IF(E8=0,"-",E24/E8) -> 0.15303858 | F25: =IF(F8=0,"-",F24/F8) -> 0.22021158 | G25: =IF(G8=0,"-",G24/G8) -> 0.25043785 | H25: =IF(H8=0,"-",H24/H8) -> 0.2515276 | I25: =IF(I8=0,"-",I24/I8) -> 0.28346264 | J25: =IF(J8=0,"-",J24/J8) -> 0.29365568 | K25: =IF(K8=0,"-",K24/K8) -> 0.30066067 | ... M25: =IF(M8=0,"-",M24/M8) -> 0.32793565
C27: Interest Expense | D27: 2500 | E27: 2500 | F27: 1500 | G27: 1500 | H27: 1500 | I27: =I100 -> 2100 | J27: =J100 -> 2100 | K27: =K100 -> 2100 | L27: =L100 -> 2100 | M27: =M100 -> 1400
C28: Earnings Before Tax | D28: =D24-D27 -> 6049.355 | E28: =E24-E27 -> 15571.714 | F28: =F24-F27 -> 27423.69 | G28: =G24-G27 -> 34147.574 | H28: =H24-H27 -> 36423.32 | I28: =I24-I27 -> 44912.052 | J28: =J24-J27 -> 51472.815 | K28: =K24-K27 -> 58235.841 | ... M28: =M24-M27 -> 75359.987
C29: Income Tax Expense | D29: 1120 | E29: 4858 | F29: 8483 | G29: 10908 | H29: 11598 | I29: =MAX(0,I28*Assumptions!I32) -> 12575.375 | J29: =MAX(0,J28*Assumptions!J32) -> 14412.388 | K29: =MAX(0,K28*Assumptions!K32) -> 16306.036 | L29: =MAX(0,L28*Assumptions!L32) -> 19165.536 | M29: =MAX(0,M28*Assumptions!M32) -> 21100.796
C30: Net Profit | D30: =D28-D29 -> 4929.355 | E30: =E28-E29 -> 10713.714 | F30: =F28-F29 -> 18940.69 | G30: =G28-G29 -> 23239.574 | H30: =H28-H29 -> 24825.32 | I30: =I28-I29 -> 32336.677 | J30: =J28-J29 -> 37060.427 | K30: =K28-K29 -> 41929.806 | ... M30: =M28-M29 -> 54259.19
C31: Net Margin (%) | D31: =IF(D8=0,"-",D30/D8) -> 0.048323693 | E31: =IF(E8=0,"-",E30/E8) -> 0.090728063 | F31: =IF(F8=0,"-",F30/F8) -> 0.14420564 | G31: =IF(G8=0,"-",G30/G8) -> 0.1632669 | H31: =IF(H8=0,"-",H30/H8) -> 0.16465471 | I31: =IF(I8=0,"-",I30/I8) -> 0.19497638 | J31: =IF(J8=0,"-",J30/J8) -> 0.20314416 | K31: =IF(K8=0,"-",K30/K8) -> 0.20894121 | ... M31: =IF(M8=0,"-",M30/M8) -> 0.23180727
C33: BALANCE SHEET ($000s)
C35: Assets
C36: Cash & Cash Equivalents | D36: 67971 | E36: 81210 | F36: 83715 | G36: 111070 | H36: 139549 | I36: =I79 -> 167988.08 | J36: =J79 -> 200385.87 | K36: =K79 -> 239107.73 | L36: =L79 -> 275177.62 | M36: =M79 -> 326519.99
C37: Accounts Receivable | D37: 5100 | E37: 5904 | F37: 6567 | G37: 7117 | H37: 7538 | I37: =I84 -> 8178.8647 | J37: =J84 -> 8996.7511 | K37: =K84 -> 9896.4262 | L37: =L84 -> 10688.14 | M37: =M84 -> 11543.192
C38: Inventory | D38: 7805 | E38: 9601 | F38: 9825 | G38: 10531 | H38: 11342 | I38: =I85 -> 13449.689 | J38: =J85 -> 15719.323 | K38: =K85 -> 17291.256 | L38: =L85 -> 18169.839 | M38: =M85 -> 19623.426
C39: Total Current Assets | D39: =D36+D37+D38 -> 80876 | E39: =E36+E37+E38 -> 96715 | F39: =F36+F37+F38 -> 100107 | G39: =G36+G37+G38 -> 128718 | H39: =H36+H37+H38 -> 158429 | I39: =I36+I37+I38 -> 189616.63 | J39: =J36+J37+J38 -> 225101.94 | K39: =K36+K37+K38 -> 266295.41 | ... M39: =M36+M37+M38 -> 357686.61
C41: Property, Plant & Equipment (net) | D41: 45500 | E41: 42350 | F41: 40145 | G41: 38601 | H41: 37521 | I41: =I94 -> 39388.65 | J41: =J94 -> 41602.622 | K41: =K94 -> 43041.705 | L41: =L94 -> 44977.108 | M41: =M94 -> 46235.12
C42: Total Assets | D42: =D39+D41 -> 126376 | E42: =E39+E41 -> 139065 | F42: =F39+F41 -> 140252 | G42: =G39+G41 -> 167319 | H42: =H39+H41 -> 195950 | I42: =I39+I41 -> 229005.28 | J42: =J39+J41 -> 266704.57 | K42: =K39+K41 -> 309337.12 | ... M42: =M39+M41 -> 403921.73
C44: Liabilities & Equity
C45: Accounts Payable | D45: 3902 | E45: 4800 | F45: 4912 | G45: 5266 | H45: 5670 | I45: =I86 -> 6388.6021 | J45: =J86 -> 7027.4623 | K45: =K86 -> 7730.2085 | L45: =L86 -> 8122.9867 | M45: =M86 -> 8772.8256
C46: Total Current Liabilities | D46: =D45 -> 3902 | E46: =E45 -> 4800 | F46: =F45 -> 4912 | G46: =G45 -> 5266 | H46: =H45 -> 5670 | I46: =I45 -> 6388.6021 | J46: =J45 -> 7027.4623 | K46: =K45 -> 7730.2085 | ... M46: =M45 -> 8772.8256
C48: Long-term Debt | D48: 50000 | E48: 50000 | F48: 30000 | G48: 30000 | H48: 30000 | I48: =I99 -> 30000 | J48: =J99 -> 30000 | K48: =K99 -> 30000 | L48: =L99 -> 20000 | M48: =M99 -> 20000
C49: Total Liabilities | D49: =D46+D48 -> 53902 | E49: =E46+E48 -> 54800 | F49: =F46+F48 -> 34912 | G49: =G46+G48 -> 35266 | H49: =H46+H48 -> 35670 | I49: =I46+I48 -> 36388.602 | J49: =J46+J48 -> 37027.462 | K49: =K46+K48 -> 37730.208 | ... M49: =M46+M48 -> 28772.826
...
